/var/www/focus/env/lib/python3.6/site-packages/urllib3/connectionpool.py:1004: InsecureRequestWarning: Unverified HTTPS request is being made. Adding certificate verification is strongly advised. See: https://urllib3.readthedocs.io/en/latest/advanced-usage.html#ssl-warnings
  InsecureRequestWarning,
error= None
Internal Server Error: /api/monitoring
Traceback (most recent call last):
  File "/var/www/focus/env/lib/python3.6/site-packages/django/db/backends/utils.py", line 61, in callproc
    return self.cursor.callproc(procname, params)
  File "/var/www/focus/env/lib/python3.6/site-packages/MySQLdb/cursors.py", line 303, in callproc
    self._query(q)
  File "/var/www/focus/env/lib/python3.6/site-packages/MySQLdb/cursors.py", line 315, in _query
    db.query(q)
  File "/var/www/focus/env/lib/python3.6/site-packages/MySQLdb/connections.py", line 226, in query
    _mysql.connection.query(self, query)
MySQLdb._exceptions.OperationalError: (2006, '')

The above exception was the direct cause of the following exception:

Traceback (most recent call last):
  File "/var/www/focus/env/lib/python3.6/site-packages/django/core/handlers/exception.py", line 34, in inner
    response = get_response(request)
  File "/var/www/focus/env/lib/python3.6/site-packages/django/core/handlers/base.py", line 115, in _get_response
    response = self.process_exception_by_middleware(e, request)
  File "/var/www/focus/env/lib/python3.6/site-packages/django/core/handlers/base.py", line 113, in _get_response
    response = wrapped_callback(request, *callback_args, **callback_kwargs)
  File "./Monitoring/views.py", line 89, in api
    return unit_toggle(request)
  File "./Monitoring/views.py", line 282, in unit_toggle
    user_id=request.user.id
  File "./Monitoring/dispatcher.py", line 194, in device_unit_toogle
    user_id=kwargs.get('user_id')
  File "./Monitoring/dispatcher.py", line 68, in send_to_broker
    result_message
  File "/var/www/focus/env/lib/python3.6/site-packages/django/db/backends/utils.py", line 64, in callproc
    return self.cursor.callproc(procname, params, kparams)
  File "/var/www/focus/env/lib/python3.6/site-packages/django/db/utils.py", line 89, in __exit__
    raise dj_exc_value.with_traceback(traceback) from exc_value
  File "/var/www/focus/env/lib/python3.6/site-packages/django/db/backends/utils.py", line 61, in callproc
    return self.cursor.callproc(procname, params)
  File "/var/www/focus/env/lib/python3.6/site-packages/MySQLdb/cursors.py", line 303, in callproc
    self._query(q)
  File "/var/www/focus/env/lib/python3.6/site-packages/MySQLdb/cursors.py", line 315, in _query
    db.query(q)
  File "/var/www/focus/env/lib/python3.6/site-packages/MySQLdb/connections.py", line 226, in query
    _mysql.connection.query(self, query)
django.db.utils.OperationalError: (2006, '')
[pid: 1874|app: 0|req: 3/5] 176.67.55.11 () {50 vars in 1081 bytes} [Tue Oct 22 07:09:17 2019] GET /api/monitoring?action=unit_toggle&device_id=1&unitID=5 => generated 14230 bytes in 51 msecs (HTTP/1.1 500) 4 headers in 145 bytes (1 switches on core 0)


